data/sample_ticks.csv
type,side,price,qty,visible_qty,order_id
L,B,99.50,100,0,1
L,S,100.50,100,0,2
L,B,99.75,50,0,3
L,S,100.25,50,0,4
L,B,100.25,80,0,5
L,S,99.75,80,0,6
M,B,,200,0,7
L,S,101.00,150,0,8
B,S,100.00,1000,100,9
L,B,100.00,100,0,10
L,B,100.00,100,0,11
C,,,,,9
L,B,99.00,500,0,12
L,S,99.00,300,0,13
